Workbook

Sheet Cover Page
B3: SUPPLY CHAIN & DISTRIBUTION ANALYTICS SYSTEM
B6: Supply Chain Performance Dashboard | FY 2023–2024
B8: [Siddharth Kaulagi | B.E. Industrial Engineering
B9: [B.M.S College of Engineering Bengaluru]
B10: April 2025
B12: NAVIGATION
D13: → Raw Data
D14: → KPI Dashboard
D15: → Inventory Analysis
D16: → Demand Forecasting
D17: → Supplier Scorecard
D18: → Logistics & Delivery
D19: → Cost Analysis
D20: → Workforce & Ops
D21: → What-If Simulator

Sheet KPI Dashboard
A1: SUPPLY CHAIN DISTRIBUTION & LOGISTICS ANALYTICS SYSTEM FY 2023–24
A6: Inventory Turnover | C6: On-Time Delivery % | E6: Forecast Accuracy | G6: Stockout Rate | I6: Avg Supplier Lead Time | K6: Distribution Cost %
A7: ='Inventory Analysis'!I4 -> 0.93917087 | C7: =AVERAGE('Logistics & Delivery'!F4:F8) -> 0.21012047 | E7: =1-AVERAGE('Demand Forecasting'!I4:I27) -> 0.71267942 | G7: =COUNTIF('Raw Data'!U4:U323,"<"&'Raw Data'!W4:W323)/COUNTA('Raw Data'!U4:U323) -> 0.2507837 | I7: =AVERAGE('Supplier Scorecard'!F4:F11) -> 10.5375 | K7: =AVERAGE('Cost Analysis'!H4:H27) -> 0.32263403
A9: Target: >4.0x | C9: Target: >90% | E9: Target: >85% | G9: Target: <5% | I9: Target: <15 Days | K9: Target: <12%
A11: SECONDARY KPI TABLE
A12: KPI Name | B12: Current Value | C12: Target | D12: Variance | E12: Status | F12: Trend | G12: Commentary | L12: KPI | M12: Actual | N12: Target
A13: Inventory Turnover | B13: ='Inventory Analysis'!I4 -> 0.93917087 | C13: 4 | D13: =B13-C13 -> -3.0608291 | E13: =IF(B13>=C13,"✔","✘") -> ✘ | F13: ▲ | G13: Above target strong stock rotation | L13: Turnover | M13: 75 | N13: 100
A14: On-Time Delivery % | B14: =AVERAGE('Logistics & Delivery'!F4:F8) -> 0.21012047 | C14: 0.9 | D14: =B14-C14 -> -0.68987953 | E14: =IF(B14>=C14,"✔","✘") -> ✘ | F14: → | G14: Stable across regions | L14: OTD | M14: 82 | N14: 100
A15: Forecast Accuracy | B15: =1-AVERAGE('Demand Forecasting'!I4:I27) -> 0.71267942 | C15: 85% | D15: =B15-C15 -> -0.13732058 | E15: =IF(B15>=C15,"✔","✘") -> ✘ | F15: ▲ | G15: 3-Month MA performs best | L15: Forecast | M15: 78 | N15: 100
A16: Stockout Rate | B16: =COUNTIF('Raw Data'!U4:U323,"<"&'Raw Data'!W4:W323)/COUNTA('Raw Data'!U4:U323) -> 0.3322884 | C16: 0.05 | D16: =B16-C16 -> 0.2822884 | E16: =IF(B16<C16,"✔","✘") -> ✘ | F16: ▼ | G16: Within acceptable limit | L16: Stockout | M16: 88 | N16: 100
A17: Avg Supplier Reliability | B17: =AVERAGE('Supplier Scorecard'!K4:K11) -> 0.83375 | C17: 0.85 | D17: =B17-C17 -> -0.01625 | E17: =IF(B17>=C17,"✔","✘") -> ✘ | F17: ▲ | G17: 3 suppliers rated A-grade | L17: LeadTime | M17: 65 | N17: 100
A18: Avg Delivery Days | B18: =AVERAGE('Logistics & Delivery'!I4:I23) -> 21.642857 | C18: 15 | D18: =B18-C18 -> 6.6428571 | E18: =IF(B18<=C18,"✔","✘") -> ✔ | F18: → | G18: Target met consistently | L18: Cost% | M18: 70 | N18: 100
A19: Freight Cost as % of Revenue | B19: =AVERAGE('Logistics & Delivery'!L4:L8) -> 0.0048927762 | C19: 8% | D19: =B19-C19 -> -0.075107224 | E19: =IF(B19<=C19,"✔","✘") -> ✔ | F19: ▼ | G19: Slight increase in Q2
A20: DC Workforce Productivity | B20: =AVERAGE('Workforce & Ops'!D4:D27) -> 1.5541667 | C20: 18 | D20: =B20-C20 -> -16.445833 | E20: =IF(B20>=C20,"✔","✘") -> ✘ | F20: ▲ | G20: Morning shift leads
A21: Safety Incident Rate | B21: =AVERAGE('Workforce & Ops'!I4:I27) -> 1.625 | C21: 1 | D21: =B21-C21 -> 0.625 | E21: =IF(B21<=C21,"✔","✘") -> ✔ | F21: → | G21: Zero incidents in 4 months
A22: Fill Rate | B22: =SUMIF('Raw Data'!T4:T323,"Yes",'Raw Data'!N4:N323)/SUM('Raw Data'!N4:N323) -> 0.23074402 | C22: 95% | D22: =B22-C22 -> -0.71925598 | E22: =IF(B22>=C22,"✔","✘") -> ✘ | F22: ▲ | G22: Service level excellent
A27: VBA_Macros Bar

Sheet Raw Data
A1: ONE DISTRIBUTORS — MASTER ORDER DATA FY2023-24
A2: Order ID | B2: Order Date | C2: Product ID | D2: Product Name | E2: Product Category | F2: Warehouse/DC | G2: Customer ID | H2: Customer Name | I2: Customer Region | J2: Customer City | K2: Supplier ID | L2: Supplier Name | M2: Supplier State | N2: Quantity Ordered | O2: Unit Price (₹) | P2: Total Order Value (₹) | Q2: Promised Delivery Days | R2: Actual Delivery Days | S2: Delay (Days) | T2: On-Time Delivery | U2: Stock On Hand (Units) | V2: Units Consumed (Period) | W2: Reorder Point | X2: Holding Cost/Unit (₹/day) | Y2: Supplier Lead Time (days) | Z2: Unit Cost (₹) | AA2: Freight Cost (₹) | AB2: Supplier Reliability Score
A3: ORD-0001 | B3: 44932 | C3: PRD-019 | D3: Gearbox Assembly | E3: Mechanical | F3: DC-HYD | G3: CUST-013 | H3: Hindustan Motors | I3: East | J3: Kolkata | K3: SUP-008 | L3: Delhi Auto Components | M3: Uttar Pradesh | N3: 570 | O3: 14209.31 | P3: =N3*O3 -> 8099306.7 | Q3: 14 | R3: 15 | S3: =MAX(0,R3-Q3) -> 1 | T3: =IF(S3=0,"Yes","No") -> No | U3: 2993 | V3: 406 | W3: 442 | X3: 25 | Y3: 35 | Z3: 10361.23 | AA3: 4698 | AB3: 0.74
A4: ORD-0002 | B4: 44933 | C4: PRD-012 | D4: Oil Filter | E4: Mechanical | F4: DC-BLR | G4: CUST-025 | H4: Wirtgen India | I4: West | J4: Pune | K4: SUP-006 | L4: Pune Precision | M4: Maharashtra | N4: 883 | O4: 729.89 | P4: =N4*O4 -> 644492.87 | Q4: 18 | R4: 24 | S4: =MAX(0,R4-Q4) -> 6 | T4: =IF(S4=0,"Yes","No") -> No | U4: 2256 | V4: 1112 | W4: 1588 | X4: 3.5 | Y4: 5 | Z4: 509.21 | AA4: 2735 | AB4: 0.82
A5: ORD-0003 | B5: 44934 | C5: PRD-003 | D5: V-Belt Set | E5: Mechanical | F5: DC-CHN | G5: CUST-022 | H5: Komatsu India | I5: South | J5: Chennai | K5: SUP-002 | L5: TN Parts Pvt. Ltd. | M5: Tamil Nadu | N5: 895 | O5: 482.11 | P5: =N5*O5 -> 431488.45 | Q5: 8 | R5: 9 | S5: =MAX(0,R5-Q5) -> 1 | T5: =IF(S5=0,"Yes","No") -> No | U5: 2222 | V5: 1158 | W5: 1638 | X5: 3 | Y5: 5 | Z5: 360.75 | AA5: 4065 | AB5: 0.88
A6: ORD-0004 | B6: 44935 | C6: PRD-018 | D6: Rivet Set | E6: Fasteners | F6: DC-BLR | G6: CUST-030 | H6: XCMG India | I6: South | J6: Hyderabad | K6: SUP-003 | L6: GujFab Ltd. | M6: Gujarat | N6: 971 | O6: 95.16 | P6: =N6*O6 -> 92400.36 | Q6: 13 | R6: 12 | S6: =MAX(0,R6-Q6) -> 0 | T6: =IF(S6=0,"Yes","No") -> Yes | U6: 458 | V6: 1156 | W6: 1050 | X6: 2 | Y6: 3 | Z6: 62.46 | AA6: 2225 | AB6: 0.9
A7: ORD-0005 | B7: 44936 | C7: PRD-005 | D7: Welding Gloves | E7: Safety | F7: DC-CHN | G7: CUST-011 | H7: Godrej Industries | I7: West | J7: Mumbai | K7: SUP-005 | L7: UP Electricals | M7: Uttar Pradesh | N7: 925 | O7: 323.02 | P7: =N7*O7 -> 298793.5 | Q7: 24 | R7: 26 | S7: =MAX(0,R7-Q7) -> 2 | T7: =IF(S7=0,"Yes","No") -> No | U7: 400 | V7: 691 | W7: 718 | X7: 2 | Y7: 4 | Z7: 201.16 | AA7: 3778 | AB7: 0.97
A8: ORD-0006 | B8: 44941 | C8: PRD-018 | D8: Rivet Set | E8: Fasteners | F8: DC-CHN | G8: CUST-009 | H8: Vedanta Resources | I8: West | J8: Ahmedabad | K8: SUP-003 | L8: GujFab Ltd. | M8: Gujarat | N8: 65 | O8: 88.26 | P8: =N8*O8 -> 5736.9 | Q8: 27 | R8: 27 | S8: =MAX(0,R8-Q8) -> 0 | T8: =IF(S8=0,"Yes","No") -> Yes | U8: 2632 | V8: 87 | W8: 99 | X8: 2 | Y8: 3 | Z8: 68.36 | AA8: 5202 | AB8: 0.78
A9: ORD-0007 | B9: 44943 | C9: PRD-001 | D9: Hydraulic Pump | E9: Hydraulics | F9: DC-HYD | G9: CUST-018 | H9: TVS Motor | I9: South | J9: Bengaluru | K9: SUP-004 | L9: RajMetals Corp | M9: Rajasthan | N9: 22 | O9: 7685.54 | P9: =N9*O9 -> 169081.88 | Q9: 28 | R9: 30 | S9: =MAX(0,R9-Q9) -> 2 | T9: =IF(S9=0,"Yes","No") -> No | U9: 2214 | V9: 32 | W9: 25 | X9: 18 | Y9: 25 | Z9: 5861.24 | AA9: 6021 | AB9: 0.82
A10: ORD-0008 | B10: 44944 | C10: PRD-012 | D10: Oil Filter | E10: Mechanical | F10: DC-BLR | G10: CUST-022 | H10: Komatsu India | I10: South | J10: Chennai | K10: SUP-001 | L10: MahaComp Industries | M10: Maharashtra | N10: 436 | O10: 679.85 | P10: =N10*O10 -> 296414.6 | Q10: 30 | R10: 38 | S10: =MAX(0,R10-Q10) -> 8 | T10: =IF(S10=0,"Yes","No") -> No | U10: 129 | V10: 443 | W10: 436 | X10: 3.5 | Y10: 5 | Z10: 497.05 | AA10: 6858 | AB10: 0.86
A11: ORD-0009 | B11: 44945 | C11: PRD-004 | D11: Safety Helmet | E11: Safety | F11: DC-DEL | G11: CUST-014 | H11: Mahindra & Mahindra | I11: West | J11: Mumbai | K11: SUP-003 | L11: GujFab Ltd. | M11: Gujarat | N11: 580 | O11: 881.68 | P11: =N11*O11 -> 511374.4 | Q11: 7 | R11: 14 | S11: =MAX(0,R11-Q11) -> 7 | T11: =IF(S11=0,"Yes","No") -> No | U11: 2555 | V11: 617 | W11: 878 | X11: 4 | Y11: 6 | Z11: 628.17 | AA11: 5862 | AB11: 0.89
A12: ORD-0010 | B12: 44946 | C12: PRD-015 | D12: Safety Boots | E12: Safety | F12: DC-BLR | G12: CUST-014 | H12: Mahindra & Mahindra | I12: West | J12: Mumbai | K12: SUP-003 | L12: GujFab Ltd. | M12: Gujarat | N12: 432 | O12: 2359.78 | P12: =N12*O12 -> 1019425 | Q12: 18 | R12: 24 | S12: =MAX(0,R12-Q12) -> 6 | T12: =IF(S12=0,"Yes","No") -> No | U12: 2524 | V12: 606 | W12: 855 | X12: 7 | Y12: 10 | Z12: 1763.15 | AA12: 1010 | AB12: 0.9
A13: ORD-0011 | B13: 44949 | C13: PRD-013 | D13: Chain Sprocket | E13: Mechanical | F13: DC-BLR | G13: CUST-027 | H13: Putzmeister | I13: South | J13: Hyderabad | K13: SUP-001 | L13: MahaComp Industries | M13: Maharashtra | N13: 773 | O13: 2290.74 | P13: =N13*O13 -> 1770742 | Q13: 7 | R13: 5 | S13: =MAX(0,R13-Q13) -> 0 | T13: =IF(S13=0,"Yes","No") -> Yes | U13: 1755 | V13: 551 | W13: 465 | X13: 6 | Y13: 9 | Z13: 1829.9 | AA13: 7825 | AB13: 0.72
A14: ORD-0012 | B14: 44955 | C14: PRD-011 | D14: Cable Harness | E14: Electrical | F14: DC-MUM | G14: CUST-027 | H14: Putzmeister | I14: South | J14: Hyderabad | K14: SUP-008 | L14: Delhi Auto Components | M14: Uttar Pradesh | N14: 675 | O14: 3148.23 | P14: =N14*O14 -> 2125055.2 | Q14: 9 | R14: 9 | S14: =MAX(0,R14-Q14) -> 0 | T14: =IF(S14=0,"Yes","No") -> Yes | U14: 176 | V14: 434 | W14: 599 | X14: 11 | Y14: 15 | Z14: 2327.22 | AA14: 1636 | AB14: 0.91
... A322: ORD-0320 | B322: 45647 | C322: PRD-003 | D322: V-Belt Set | E322: Mechanical | F322: DC-HYD | G322: CUST-004 | H322: Thermax Ltd. | I322: West | J322: Pune | K322: SUP-008 | L322: Delhi Auto Components | M322: Uttar Pradesh | N322: 201 | O322: 446.15 | P322: =N322*O322 -> 89676.15 | Q322: 11 | R322: 11 | S322: =MAX(0,R322-Q322) -> 0 | T322: =IF(S322=0,"Yes","No") -> Yes | U322: 1094 | V322: 222 | W322: 253 | X322: 3 | Y322: 5 | Z322: 353.88 | AA322: 3067 | AB322: 0.87

Sheet Inventory Analysis
A1: INVENTORY ANALYSIS — ABC CLASSIFICATION & STOCK HEALTH
A3: Product ID | B3: Product Name | C3: Category | D3: DC Location | E3: Avg Stock (Units) | F3: Total Consumed | G3: COGS (₹) | H3: Avg Stock Value (₹) | I3: Inventory Turnover | J3: Days Inventory Outstanding | K3: Reorder Point | L3: Stockout Risk | M3: ABC Class
A4: PRD-001 | B4: Hydraulic Pump | C4: Hydraulics | D4: DC-BLR | E4: 1820 | F4: 2402 | G4: 17710357 | H4: =E4*'Raw Data'!Z3 -> 18857439 | I4: =IF(H4=0,0,G4/H4) -> 0.93917087 | J4: =IF(I4=0,"N/A",365/I4) -> 388.64067 | K4: 562 | L4: =IF(E4<K4,"HIGH RISK",IF(E4<2*K4,"WATCH","SAFE")) -> SAFE | M4: A
A5: PRD-001 | B5: Hydraulic Pump | C5: Hydraulics | D5: DC-CHN | E5: 2316 | F5: 2277 | G5: 17263906 | H5: =E5*'Raw Data'!Z4 -> 1179330.4 | I5: =IF(H5=0,0,G5/H5) -> 14.638736 | J5: =IF(I5=0,"N/A",365/I5) -> 24.933847 | K5: 608 | L5: =IF(E5<K5,"HIGH RISK",IF(E5<2*K5,"WATCH","SAFE")) -> SAFE | M5: A
A6: PRD-019 | B6: Gearbox Assembly | C6: Mechanical | D6: DC-CHN | E6: 1873 | F6: 1742 | G6: 15759975 | H6: =E6*'Raw Data'!Z5 -> 675684.75 | I6: =IF(H6=0,0,G6/H6) -> 23.32445 | J6: =IF(I6=0,"N/A",365/I6) -> 15.648815 | K6: 476 | L6: =IF(E6<K6,"HIGH RISK",IF(E6<2*K6,"WATCH","SAFE")) -> SAFE | M6: B
A7: PRD-007 | B7: Pneumatic Valve | C7: Hydraulics | D7: DC-HYD | E7: 1401 | F7: 2550 | G7: 11865847 | H7: =E7*'Raw Data'!Z6 -> 87506.46 | I7: =IF(H7=0,0,G7/H7) -> 135.59967 | J7: =IF(I7=0,"N/A",365/I7) -> 2.6917469 | K7: 748 | L7: =IF(E7<K7,"HIGH RISK",IF(E7<2*K7,"WATCH","SAFE")) -> WATCH | M7: B
A8: PRD-019 | B8: Gearbox Assembly | C8: Mechanical | D8: DC-HYD | E8: 2288 | F8: 867 | G8: 11279711 | H8: =E8*'Raw Data'!Z7 -> 460254.08 | I8: =IF(H8=0,0,G8/H8) -> 24.507574 | J8: =IF(I8=0,"N/A",365/I8) -> 14.893355 | K8: 472 | L8: =IF(E8<K8,"HIGH RISK",IF(E8<2*K8,"WATCH","SAFE")) -> SAFE | M8: B
A9: PRD-001 | B9: Hydraulic Pump | C9: Hydraulics | D9: DC-MUM | E9: 1352 | F9: 1901 | G9: 11277543 | H9: =E9*'Raw Data'!Z8 -> 92422.72 | I9: =IF(H9=0,0,G9/H9) -> 122.02132 | J9: =IF(I9=0,"N/A",365/I9) -> 2.9912805 | K9: 569 | L9: =IF(E9<K9,"HIGH RISK",IF(E9<2*K9,"WATCH","SAFE")) -> SAFE | M9: B
A10: PRD-019 | B10: Gearbox Assembly | C10: Mechanical | D10: DC-BLR | E10: 1977 | F10: 1194 | G10: 8778741.4 | H10: =E10*'Raw Data'!Z9 -> 11587671 | I10: =IF(H10=0,0,G10/H10) -> 0.75759322 | J10: =IF(I10=0,"N/A",365/I10) -> 481.78889 | K10: 708 | L10: =IF(E10<K10,"HIGH RISK",IF(E10<2*K10,"WATCH","SAFE")) -> SAFE | M10: B
A11: PRD-001 | B11: Hydraulic Pump | C11: Hydraulics | D11: DC-HYD | E11: 1600 | F11: 1234 | G11: 7279215 | H11: =E11*'Raw Data'!Z10 -> 795280 | I11: =IF(H11=0,0,G11/H11) -> 9.1530216 | J11: =IF(I11=0,"N/A",365/I11) -> 39.877542 | K11: 413 | L11: =IF(E11<K11,"HIGH RISK",IF(E11<2*K11,"WATCH","SAFE")) -> SAFE | M11: B
A12: PRD-007 | B12: Pneumatic Valve | C12: Hydraulics | D12: DC-CHN | E12: 1282 | F12: 1288 | G12: 7194601.7 | H12: =E12*'Raw Data'!Z11 -> 805313.94 | I12: =IF(H12=0,0,G12/H12) -> 8.9339093 | J12: =IF(I12=0,"N/A",365/I12) -> 40.855575 | K12: 574 | L12: =IF(E12<K12,"HIGH RISK",IF(E12<2*K12,"WATCH","SAFE")) -> SAFE | M12: B
A13: PRD-001 | B13: Hydraulic Pump | C13: Hydraulics | D13: DC-DEL | E13: 1241 | F13: 1217 | G13: 6204200.4 | H13: =E13*'Raw Data'!Z12 -> 2188069.1 | I13: =IF(H13=0,0,G13/H13) -> 2.8354681 | J13: =IF(I13=0,"N/A",365/I13) -> 128.72654 | K13: 807 | L13: =IF(E13<K13,"HIGH RISK",IF(E13<2*K13,"WATCH","SAFE")) -> WATCH | M13: B
A14: PRD-017 | B14: Cylinder Seal Kit | C14: Hydraulics | D14: DC-BLR | E14: 1697 | F14: 1779 | G14: 6004605.8 | H14: =E14*'Raw Data'!Z13 -> 3105340.3 | I14: =IF(H14=0,0,G14/H14) -> 1.9336386 | J14: =IF(I14=0,"N/A",365/I14) -> 188.7633 | K14: 439 | L14: =IF(E14<K14,"HIGH RISK",IF(E14<2*K14,"WATCH","SAFE")) -> SAFE | M14: B
A15: PRD-015 | B15: Safety Boots | C15: Safety | D15: DC-MUM | E15: 1697 | F15: 2625 | G15: 5877437 | H15: =E15*'Raw Data'!Z14 -> 3949292.3 | I15: =IF(H15=0,0,G15/H15) -> 1.4882253 | J15: =IF(I15=0,"N/A",365/I15) -> 245.25856 | K15: 467 | L15: =IF(E15<K15,"HIGH RISK",IF(E15<2*K15,"WATCH","SAFE")) -> SAFE | M15: C
... A97: PRD-020 | B97: Dust Mask N95 | C97: Safety | D97: DC-BLR | E97: 2606 | F97: 108 | G97: 18223.68 | H97: =E97*'Raw Data'!Z96 -> 2593647.6 | I97: =IF(H97=0,0,G97/H97) -> 0.0070262746 | J97: =IF(I97=0,"N/A",365/I97) -> 51947.87 | K97: 107 | L97: =IF(E97<K97,"HIGH RISK",IF(E97<2*K97,"WATCH","SAFE")) -> SAFE | M97: C
A100: ABC CLASSIFICATION SUMMARY
A101: Class | B101: Item Count | C101: % of Total COGS | D101: Recommendation
A102: A | B102: 2 | C102: =B102/94 -> 0.021276596 | D102: Tight control, frequent review, priority replenishment
A103: B | B103: 9 | C103: =B103/94 -> 0.095744681 | D103: Moderate control, periodic review, standard reorder
A104: C | B104: 83 | C104: =B104/94 -> 0.88297872 | D104: Loose control, bulk ordering, minimize handling

Sheet Demand Forecasting
A1: DEMAND FORECASTING — MONTHLY DEMAND & MOVING AVERAGES
A3: Month | B3: Actual Demand (Units) | C3: Actual Demand (₹) | D3: 3-Month MA (Units) | E3: 5-Month MA (Units) | F3: Exponential Smoothing (α=0.3) | G3: Forecast for Next Month | H3: Absolute Error | I3: MAPE (%) | J3: Cumulative MAPE
A4: 2023-01 | B4: 9261 | C4: 19305037 | F4: =B4 -> 9261 | H4: =ABS(B4-G4) -> 9261 | I4: =IF(B4=0,0,H4/B4) -> 1 | J4: =I4 -> 1
A5: 2023-02 | B5: 4533 | C5: 11445542 | F5: =0.3*B5+0.7*F4 -> 7842.6 | H5: =ABS(B5-G5) -> 4533 | I5: =IF(B5=0,0,H5/B5) -> 1 | J5: =AVERAGE(I$4:I5) -> 1
A6: 2023-03 | B6: 5729 | C6: 13277762 | D6: =AVERAGE(B4:B6) -> 6507.6667 | F6: =0.3*B6+0.7*F5 -> 7208.52 | G6: =D6 -> 6507.6667 | H6: =ABS(B6-G6) -> 778.66667 | I6: =IF(B6=0,0,H6/B6) -> 0.13591668 | J6: =AVERAGE(I$4:I6) -> 0.71197223
A7: 2023-04 | B7: 5359 | C7: 14315175 | D7: =AVERAGE(B5:B7) -> 5207 | F7: =0.3*B7+0.7*F6 -> 6653.664 | G7: =D7 -> 5207 | H7: =ABS(B7-G7) -> 152 | I7: =IF(B7=0,0,H7/B7) -> 0.028363501 | J7: =AVERAGE(I$4:I7) -> 0.54107005
A8: 2023-05 | B8: 4198 | C8: 3598995.6 | D8: =AVERAGE(B6:B8) -> 5095.3333 | E8: =AVERAGE(B4:B8) -> 5816 | F8: =0.3*B8+0.7*F7 -> 5916.9648 | G8: =D8 -> 5095.3333 | H8: =ABS(B8-G8) -> 897.33333 | I8: =IF(B8=0,0,H8/B8) -> 0.21375258 | J8: =AVERAGE(I$4:I8) -> 0.47560655
A9: 2023-06 | B9: 8253 | C9: 20628042 | D9: =AVERAGE(B7:B9) -> 5936.6667 | E9: =AVERAGE(B5:B9) -> 5614.4 | F9: =0.3*B9+0.7*F8 -> 6617.7754 | G9: =D9 -> 5936.6667 | H9: =ABS(B9-G9) -> 2316.3333 | I9: =IF(B9=0,0,H9/B9) -> 0.28066562 | J9: =AVERAGE(I$4:I9) -> 0.4431164
A10: 2023-07 | B10: 7709 | C10: 22295629 | D10: =AVERAGE(B8:B10) -> 6720 | E10: =AVERAGE(B6:B10) -> 6249.6 | F10: =0.3*B10+0.7*F9 -> 6945.1428 | G10: =D10 -> 6720 | H10: =ABS(B10-G10) -> 989 | I10: =IF(B10=0,0,H10/B10) -> 0.12829161 | J10: =AVERAGE(I$4:I10) -> 0.39814143
A11: 2023-08 | B11: 5557 | C11: 20407154 | D11: =AVERAGE(B9:B11) -> 7173 | E11: =AVERAGE(B7:B11) -> 6215.2 | F11: =0.3*B11+0.7*F10 -> 6528.6999 | G11: =D11 -> 7173 | H11: =ABS(B11-G11) -> 1616 | I11: =IF(B11=0,0,H11/B11) -> 0.29080439 | J11: =AVERAGE(I$4:I11) -> 0.3847243
A12: 2023-09 | B12: 10739 | C12: 42227561 | D12: =AVERAGE(B10:B12) -> 8001.6667 | E12: =AVERAGE(B8:B12) -> 7291.2 | F12: =0.3*B12+0.7*F11 -> 7791.7899 | G12: =D12 -> 8001.6667 | H12: =ABS(B12-G12) -> 2737.3333 | I12: =IF(B12=0,0,H12/B12) -> 0.25489648 | J12: =AVERAGE(I$4:I12) -> 0.37029898
A13: 2023-10 | B13: 9088 | C13: 11355771 | D13: =AVERAGE(B11:B13) -> 8461.3333 | E13: =AVERAGE(B9:B13) -> 8269.2 | F13: =0.3*B13+0.7*F12 -> 8180.653 | G13: =D13 -> 8461.3333 | H13: =ABS(B13-G13) -> 626.66667 | I13: =IF(B13=0,0,H13/B13) -> 0.068955399 | J13: =AVERAGE(I$4:I13) -> 0.34016463
A14: 2023-11 | B14: 7552 | C14: 14788407 | D14: =AVERAGE(B12:B14) -> 9126.3333 | E14: =AVERAGE(B10:B14) -> 8129 | F14: =0.3*B14+0.7*F13 -> 7992.0571 | G14: =D14 -> 9126.3333 | H14: =ABS(B14-G14) -> 1574.3333 | I14: =IF(B14=0,0,H14/B14) -> 0.20846575 | J14: =AVERAGE(I$4:I14) -> 0.328192
A15: 2023-12 | B15: 6759 | C15: 4361846 | D15: =AVERAGE(B13:B15) -> 7799.6667 | E15: =AVERAGE(B11:B15) -> 7939 | F15: =0.3*B15+0.7*F14 -> 7622.14 | G15: =D15 -> 7799.6667 | H15: =ABS(B15-G15) -> 1040.6667 | I15: =IF(B15=0,0,H15/B15) -> 0.15396755 | J15: =AVERAGE(I$4:I15) -> 0.3136733
A16: 2024-01 | B16: 4672 | C16: 7458522.1 | D16: =AVERAGE(B14:B16) -> 6327.6667 | E16: =AVERAGE(B12:B16) -> 7762 | F16: =0.3*B16+0.7*F15 -> 6737.098 | G16: =D16 -> 6327.6667 | H16: =ABS(B16-G16) -> 1655.6667 | I16: =IF(B16=0,0,H16/B16) -> 0.35438071 | J16: =AVERAGE(I$4:I16) -> 0.31680464
A17: 2024-02 | B17: 8253 | C17: 8282226.7 | D17: =AVERAGE(B15:B17) -> 6561.3333 | E17: =AVERAGE(B13:B17) -> 7264.8 | F17: =0.3*B17+0.7*F16 -> 7191.8686 | G17: =D17 -> 6561.3333 | H17: =ABS(B17-G17) -> 1691.6667 | I17: =IF(B17=0,0,H17/B17) -> 0.20497597 | J17: =AVERAGE(I$4:I17) -> 0.30881687
A18: 2024-03 | B18: 8772 | C18: 11910438 | D18: =AVERAGE(B16:B18) -> 7232.3333 | E18: =AVERAGE(B14:B18) -> 7201.6 | F18: =0.3*B18+0.7*F17 -> 7665.908 | G18: =D18 -> 7232.3333 | H18: =ABS(B18-G18) -> 1539.6667 | I18: =IF(B18=0,0,H18/B18) -> 0.1755206 | J18: =AVERAGE(I$4:I18) -> 0.29993046
A19: 2024-04 | B19: 7896 | C19: 10554169 | D19: =AVERAGE(B17:B19) -> 8307 | E19: =AVERAGE(B15:B19) -> 7270.4 | F19: =0.3*B19+0.7*F18 -> 7734.9356 | G19: =D19 -> 8307 | H19: =ABS(B19-G19) -> 411 | I19: =IF(B19=0,0,H19/B19) -> 0.052051672 | J19: =AVERAGE(I$4:I19) -> 0.28443803
... A27: 2024-12 | B27: 5652 | C27: 9322542.7 | D27: =AVERAGE(B25:B27) -> 7366 | E27: =AVERAGE(B23:B27) -> 6270 | F27: =0.3*B27+0.7*F26 -> 6538.0293 | G27: =D27 -> 7366 | H27: =ABS(B27-G27) -> 1714 | I27: =IF(B27=0,0,H27/B27) -> 0.30325548 | J27: =AVERAGE(I$4:I27) -> 0.28732058
A29: FORECAST SUMMARY
A30: Avg Monthly Demand (Units) | B30: =AVERAGE(B4:B27) -> 6761.9167
A31: Peak Demand Month | B31: {=INDEX(A4:A27,MATCH(MAX(B4:B27),B4:B27,0))} -> 2023-09
A32: Lowest Demand Month | B32: {=INDEX(A4:A27,MATCH(MIN(B4:B27),B4:B27,0))} -> 2024-05
A33: Best Forecast Method (lowest avg MAPE) | B33: 3-Month MA
A34: Avg MAPE for 3-MA | B34: =AVERAGE(I6:I27) -> 0.22253155
A35: Avg MAPE for 5-MA | B35: =AVERAGE(I8:I27) -> 0.23657069
A37: FORECAST FOR NEXT 3 MONTHS (Based on Best Method)
A38: Jan-2025 | B38: =D27 -> 7366
A39: Feb-2025 | B39: =D27 -> 7366
A40: Mar-2025 | B40: =D27 -> 7366

Sheet Supplier Scorecard
A1: SUPPLIER SCORECARD — PERFORMANCE & RISK EVALUATION
A3: Supplier ID | B3: Supplier Name | C3: State | D3: Category Supplied | E3: Total Orders | F3: Avg Lead Time (Days) | G3: Min Lead Time | H3: Max Lead Time | I3: Avg Unit Cost (₹) | J3: Total Spend (₹) | K3: Reliability Score | L3: Late Deliveries | M3: On-Time Deliveries | N3: OTD % | O3: Performance Grade | P3: Risk Flag
A4: SUP-001 | B4: MahaComp Industries | C4: Maharashtra | D4: Mechanical, Hydraulics | E4: 31 | F4: 16.7 | G4: 5 | H4: 35 | I4: 3721.59 | J4: 83447718 | K4: 0.84 | L4: 24 | M4: 7 | N4: =M4/E4 -> 0.22580645 | O4: =IF(K4>=0.93,"A – Preferred",IF(K4>=0.85,"B – Acceptable",IF(K4>=0.78,"C – Monitor","D – Exit"))) -> C – Monitor | P4: =IF(AND(F4>20,K4<0.85),"HIGH RISK",IF(OR(F4>20,K4<0.85),"MODERATE","LOW")) -> MODERATE
A5: SUP-002 | B5: TN Parts Pvt. Ltd. | C5: Tamil Nadu | D5: Mechanical, Electrical | E5: 22 | F5: 10.7 | G5: 5 | H5: 35 | I5: 1613.1 | J5: 22251394 | K5: 0.81 | L5: 21 | M5: 1 | N5: =M5/E5 -> 0.045454545 | O5: =IF(K5>=0.93,"A – Preferred",IF(K5>=0.85,"B – Acceptable",IF(K5>=0.78,"C – Monitor","D – Exit"))) -> C – Monitor | P5: =IF(AND(F5>20,K5<0.85),"HIGH RISK",IF(OR(F5>20,K5<0.85),"MODERATE","LOW")) -> MODERATE
A6: SUP-003 | B6: GujFab Ltd. | C6: Gujarat | D6: Fasteners, Safety | E6: 61 | F6: 4.7 | G6: 2 | H6: 10 | I6: 444.48 | J6: 17992927 | K6: 0.83 | L6: 46 | M6: 15 | N6: =M6/E6 -> 0.24590164 | O6: =IF(K6>=0.93,"A – Preferred",IF(K6>=0.85,"B – Acceptable",IF(K6>=0.78,"C – Monitor","D – Exit"))) -> C – Monitor | P6: =IF(AND(F6>20,K6<0.85),"HIGH RISK",IF(OR(F6>20,K6<0.85),"MODERATE","LOW")) -> MODERATE
A7: SUP-004 | B7: RajMetals Corp | C7: Rajasthan | D7: Hydraulics, Mechanical | E7: 37 | F7: 13.5 | G7: 5 | H7: 35 | I7: 2497.76 | J7: 48180673 | K7: 0.86 | L7: 28 | M7: 9 | N7: =M7/E7 -> 0.24324324 | O7: =IF(K7>=0.93,"A – Preferred",IF(K7>=0.85,"B – Acceptable",IF(K7>=0.78,"C – Monitor","D – Exit"))) -> B – Acceptable | P7: =IF(AND(F7>20,K7<0.85),"HIGH RISK",IF(OR(F7>20,K7<0.85),"MODERATE","LOW")) -> LOW
A8: SUP-005 | B8: UP Electricals | C8: Uttar Pradesh | D8: Safety, Electrical | E8: 50 | F8: 7.4 | G8: 4 | H8: 15 | I8: 905.04 | J8: 30153436 | K8: 0.84 | L8: 41 | M8: 9 | N8: =M8/E8 -> 0.18 | O8: =IF(K8>=0.93,"A – Preferred",IF(K8>=0.85,"B – Acceptable",IF(K8>=0.78,"C – Monitor","D – Exit"))) -> C – Monitor | P8: =IF(AND(F8>20,K8<0.85),"HIGH RISK",IF(OR(F8>20,K8<0.85),"MODERATE","LOW")) -> MODERATE
A9: SUP-006 | B9: Pune Precision | C9: Maharashtra | D9: Mechanical, Fasteners | E9: 53 | F9: 4.6 | G9: 2 | H9: 35 | I9: 505.4 | J9: 20494683 | K9: 0.83 | L9: 40 | M9: 13 | N9: =M9/E9 -> 0.24528302 | O9: =IF(K9>=0.93,"A – Preferred",IF(K9>=0.85,"B – Acceptable",IF(K9>=0.78,"C – Monitor","D – Exit"))) -> C – Monitor | P9: =IF(AND(F9>20,K9<0.85),"HIGH RISK",IF(OR(F9>20,K9<0.85),"MODERATE","LOW")) -> MODERATE
A10: SUP-007 | B10: Chennai Hydraulics | C10: Tamil Nadu | D10: Hydraulics | E10: 35 | F10: 16.2 | G10: 7 | H10: 25 | I10: 3176.25 | J10: 83871141 | K10: 0.82 | L10: 27 | M10: 8 | N10: =M10/E10 -> 0.22857143 | O10: =IF(K10>=0.93,"A – Preferred",IF(K10>=0.85,"B – Acceptable",IF(K10>=0.78,"C – Monitor","D – Exit"))) -> C – Monitor | P10: =IF(AND(F10>20,K10<0.85),"HIGH RISK",IF(OR(F10>20,K10<0.85),"MODERATE","LOW")) -> MODERATE
A11: SUP-008 | B11: Delhi Auto Components | C11: Uttar Pradesh | D11: Mechanical, Electrical | E11: 31 | F11: 10.5 | G11: 5 | H11: 35 | I11: 1762.67 | J11: 43093327 | K11: 0.84 | L11: 21 | M11: 10 | N11: =M11/E11 -> 0.32258065 | O11: =IF(K11>=0.93,"A – Preferred",IF(K11>=0.85,"B – Acceptable",IF(K11>=0.78,"C – Monitor","D – Exit"))) -> C – Monitor | P11: =IF(AND(F11>20,K11<0.85),"HIGH RISK",IF(OR(F11>20,K11<0.85),"MODERATE","LOW")) -> MODERATE

Sheet Logistics & Delivery
A1: LOGISTICS & DELIVERY ANALYSIS — REGIONAL & CITY PERFORMANCE
A3: Region | B3: City | C3: Total Shipments | D3: On-Time | E3: Late | F3: OTD % | G3: Avg Delay (Days) | H3: Max Delay (Days) | I3: Avg Delivery Days | J3: Total Freight Cost (₹) | K3: Revenue (₹) | L3: Freight as % of Revenue | M3: Status
A4: West | B4: (Regional) | C4: 139 | D4: 28 | E4: 111 | F4: =D4/C4 -> 0.20143885 | G4: 4.3 | H4: 13 | I4: 22.1 | J4: 593374 | K4: 1.5537669e+08 | L4: =J4/K4 -> 0.0038189384 | M4: =IF(F4>=0.9,"Good",IF(F4>=0.75,"Watch","Alert")) -> Alert
A5: West | B5: Mumbai | C5: 56 | D5: 12 | E5: 44 | F5: =D5/C5 -> 0.21428571 | G5: 4.8 | H5: 12 | I5: 23.4 | J5: 237694 | K5: 61508255 | L5: =J5/K5 -> 0.0038644244 | M5: =IF(F5>=0.9,"Good",IF(F5>=0.75,"Watch","Alert")) -> Alert
A6: West | B6: Pune | C6: 71 | D6: 14 | E6: 57 | F6: =D6/C6 -> 0.1971831 | G6: 4.1 | H6: 13 | I6: 21.2 | J6: 295980 | K6: 86637880 | L6: =J6/K6 -> 0.0034162886 | M6: =IF(F6>=0.9,"Good",IF(F6>=0.75,"Watch","Alert")) -> Alert
A7: West | B7: Ahmedabad | C7: 12 | D7: 2 | E7: 10 | F7: =D7/C7 -> 0.16666667 | G7: 3.2 | H7: 8 | I7: 20.9 | J7: 59700 | K7: 7230550.7 | L7: =J7/K7 -> 0.0082566326 | M7: =IF(F7>=0.9,"Good",IF(F7>=0.75,"Watch","Alert")) -> Alert
A8: South | B8: (Regional) | C8: 107 | D8: 29 | E8: 78 | F8: =D8/C8 -> 0.27102804 | G8: 3.8 | H8: 13 | I8: 22.4 | J8: 474306 | K8: 92862850 | L8: =J8/K8 -> 0.0051075968 | M8: =IF(F8>=0.9,"Good",IF(F8>=0.75,"Watch","Alert")) -> Alert
A9: South | B9: Hyderabad | C9: 24 | D9: 6 | E9: 18 | F9: =D9/C9 -> 0.25 | G9: 4.2 | H9: 10 | I9: 22.3 | J9: 101432 | K9: 31391383 | L9: =J9/K9 -> 0.0032312052 | M9: =IF(F9>=0.9,"Good",IF(F9>=0.75,"Watch","Alert")) -> Alert
A10: South | B10: Chennai | C10: 60 | D10: 16 | E10: 44 | F10: =D10/C10 -> 0.26666667 | G10: 3.9 | H10: 13 | I10: 22.1 | J10: 279128 | K10: 48103854 | L10: =J10/K10 -> 0.0058026119 | M10: =IF(F10>=0.9,"Good",IF(F10>=0.75,"Watch","Alert")) -> Alert
A11: South | B11: Bengaluru | C11: 23 | D11: 7 | E11: 16 | F11: =D11/C11 -> 0.30434783 | G11: 3.3 | H11: 8 | I11: 23.4 | J11: 93746 | K11: 13367613 | L11: =J11/K11 -> 0.0070129199 | M11: =IF(F11>=0.9,"Good",IF(F11>=0.75,"Watch","Alert")) -> Alert
A12: North | B12: (Regional) | C12: 40 | D12: 9 | E12: 31 | F12: =D12/C12 -> 0.225 | G12: 4 | H12: 12 | I12: 20.8 | J12: 188845 | K12: 35232214 | L12: =J12/K12 -> 0.0053600094 | M12: =IF(F12>=0.9,"Good",IF(F12>=0.75,"Watch","Alert")) -> Alert
A13: North | B13: Delhi | C13: 40 | D13: 9 | E13: 31 | F13: =D13/C13 -> 0.225 | G13: 4 | H13: 12 | I13: 20.8 | J13: 188845 | K13: 35232214 | L13: =J13/K13 -> 0.0053600094 | M13: =IF(F13>=0.9,"Good",IF(F13>=0.75,"Watch","Alert")) -> Alert
A14: East | B14: (Regional) | C14: 23 | D14: 5 | E14: 18 | F14: =D14/C14 -> 0.2173913 | G14: 3.1 | H14: 9 | I14: 18.9 | J14: 113248 | K14: 50631738 | L14: =J14/K14 -> 0.0022366998 | M14: =IF(F14>=0.9,"Good",IF(F14>=0.75,"Watch","Alert")) -> Alert
A15: East | B15: Kolkata | C15: 23 | D15: 5 | E15: 18 | F15: =D15/C15 -> 0.2173913 | G15: 3.1 | H15: 9 | I15: 18.9 | J15: 113248 | K15: 50631738 | L15: =J15/K15 -> 0.0022366998 | M15: =IF(F15>=0.9,"Good",IF(F15>=0.75,"Watch","Alert")) -> Alert
... A17: Central | B17: Delhi | C17: 11 | D17: 1 | E17: 10 | F17: =D17/C17 -> 0.090909091 | G17: 5.5 | H17: 12 | I17: 22.9 | J17: 53694 | K17: 15381811 | L17: =J17/K17 -> 0.0034907464 | M17: =IF(F17>=0.9,"Good",IF(F17>=0.75,"Watch","Alert")) -> Alert
L20: Month | M20: Revenue | N20: Freight Cost
L21: 2023-01 | M21: ='Cost Analysis'!F4 -> 19305037 | N21: 76369
L22: 2023-02 | M22: ='Cost Analysis'!F5 -> 11445542 | N22: 36958
L23: 2023-03 | M23: ='Cost Analysis'!F6 -> 13277762 | N23: 88432
L24: 2023-04 | M24: ='Cost Analysis'!F7 -> 14315175 | N24: 65330
L25: 2023-05 | M25: ='Cost Analysis'!F8 -> 3598995.6 | N25: 41756
L26: 2023-06 | M26: ='Cost Analysis'!F9 -> 20628042 | N26: 58475
L27: 2023-07 | M27: ='Cost Analysis'!F10 -> 22295629 | N27: 85960
L28: 2023-08 | M28: ='Cost Analysis'!F11 -> 20407154 | N28: 61132
L29: 2023-09 | M29: ='Cost Analysis'!F12 -> 42227561 | N29: 95673
L30: 2023-10 | M30: ='Cost Analysis'!F13 -> 11355771 | N30: 59687
L31: 2023-11 | M31: ='Cost Analysis'!F14 -> 14788407 | N31: 74001
L32: 2023-12 | M32: ='Cost Analysis'!F15 -> 4361846 | N32: 36698
... L44: 2024-12 | M44: ='Cost Analysis'!F27 -> 9322542.7 | N44: 41680
L47: Month | M47: On-Time | N47: Late
L48: Jan-2023 | M48: 6 | N48: 10
L49: Feb-2023 | M49: 3 | N49: 5
L50: Mar-2023 | M50: 5 | N50: 12
L51: Apr-2023 | M51: 0 | N51: 12
L52: May-2023 | M52: 0 | N52: 9
L53: Jun-2023 | M53: 0 | N53: 13
L54: Jul-2023 | M54: 4 | N54: 15
L55: Aug-2023 | M55: 1 | N55: 11
L56: Sep-2023 | M56: 6 | N56: 13
L57: Oct-2023 | M57: 2 | N57: 13
...

Sheet Cost Analysis
A1: COST ANALYSIS — DISTRIBUTION COST STRUCTURE & MARGIN TRACKING
A3: Month | B3: Total Procurement Cost (₹) | C3: Total Freight Cost (₹) | D3: Total Holding Cost (₹) | E3: Total Distribution Cost (₹) | F3: Revenue (₹) | G3: Gross Margin (₹) | H3: Distribution Cost as % of Revenue | I3: Cost per Unit Shipped (₹)
A4: Jan-2023 | B4: 2.6167428e+08 | C4: 76369 | D4: 5369895 | E4: =C4+D4 -> 5446264 | F4: 19305037 | G4: =F4-B4 -> -2.4236924e+08 | H4: =IF(F4=0,0,E4/F4) -> 0.28211622 | I4: =IF(J4=0,0,E4/J4) -> 588.08595 | J4: 9261
A5: Feb-2023 | B5: 61438423 | C5: 36958 | D5: 1844430 | E5: =C5+D5 -> 1881388 | F5: 11445542 | G5: =F5-B5 -> -49992881 | H5: =IF(F5=0,0,E5/F5) -> 0.16437736 | I5: =IF(J5=0,0,E5/J5) -> 415.04258 | J5: 4533
A6: Mar-2023 | B6: 1.7350059e+08 | C6: 88432 | D6: 7134960 | E6: =C6+D6 -> 7223392 | F6: 13277762 | G6: =F6-B6 -> -1.6022283e+08 | H6: =IF(F6=0,0,E6/F6) -> 0.5440218 | I6: =IF(J6=0,0,E6/J6) -> 1260.8469 | J6: 5729
A7: Apr-2023 | B7: 1.1433668e+08 | C7: 65330 | D7: 4774115.5 | E7: =C7+D7 -> 4839445.5 | F7: 14315175 | G7: =F7-B7 -> -1.000215e+08 | H7: =IF(F7=0,0,E7/F7) -> 0.338064 | I7: =IF(J7=0,0,E7/J7) -> 903.0501 | J7: 5359
A8: May-2023 | B8: 31085350 | C8: 41756 | D8: 1725518 | E8: =C8+D8 -> 1767274 | F8: 3598995.6 | G8: =F8-B8 -> -27486355 | H8: =IF(F8=0,0,E8/F8) -> 0.49104644 | I8: =IF(J8=0,0,E8/J8) -> 420.97999 | J8: 4198
A9: Jun-2023 | B9: 1.5985227e+08 | C9: 58475 | D9: 2713425 | E9: =C9+D9 -> 2771900 | F9: 20628042 | G9: =F9-B9 -> -1.3922423e+08 | H9: =IF(F9=0,0,E9/F9) -> 0.13437533 | I9: =IF(J9=0,0,E9/J9) -> 335.86575 | J9: 8253
A10: Jul-2023 | B10: 3.0324246e+08 | C10: 85960 | D10: 6655139.4 | E10: =C10+D10 -> 6741099.4 | F10: 22295629 | G10: =F10-B10 -> -2.8094683e+08 | H10: =IF(F10=0,0,E10/F10) -> 0.30235072 | I10: =IF(J10=0,0,E10/J10) -> 874.44537 | J10: 7709
A11: Aug-2023 | B11: 1.7828134e+08 | C11: 61132 | D11: 5035230 | E11: =C11+D11 -> 5096362 | F11: 20407154 | G11: =F11-B11 -> -1.5787419e+08 | H11: =IF(F11=0,0,E11/F11) -> 0.24973409 | I11: =IF(J11=0,0,E11/J11) -> 917.10671 | J11: 5557
A12: Sep-2023 | B12: 5.805919e+08 | C12: 95673 | D12: 8219945.7 | E12: =C12+D12 -> 8315618.7 | F12: 42227561 | G12: =F12-B12 -> -5.3836434e+08 | H12: =IF(F12=0,0,E12/F12) -> 0.19692397 | I12: =IF(J12=0,0,E12/J12) -> 774.33827 | J12: 10739
A13: Oct-2023 | B13: 1.2669481e+08 | C13: 59687 | D13: 2583432 | E13: =C13+D13 -> 2643119 | F13: 11355771 | G13: =F13-B13 -> -115339037 | H13: =IF(F13=0,0,E13/F13) -> 0.23275557 | I13: =IF(J13=0,0,E13/J13) -> 290.83616 | J13: 9088
A14: Nov-2023 | B14: 1.0769031e+08 | C14: 74001 | D14: 3674445.8 | E14: =C14+D14 -> 3748446.8 | F14: 14788407 | G14: =F14-B14 -> -92901905 | H14: =IF(F14=0,0,E14/F14) -> 0.25347198 | I14: =IF(J14=0,0,E14/J14) -> 496.35153 | J14: 7552
A15: Dec-2023 | B15: 42451522 | C15: 36698 | D15: 1616010 | E15: =C15+D15 -> 1652708 | F15: 4361846 | G15: =F15-B15 -> -38089676 | H15: =IF(F15=0,0,E15/F15) -> 0.37890104 | I15: =IF(J15=0,0,E15/J15) -> 244.5196 | J15: 6759
... A27: Dec-2024 | B27: 89401471 | C27: 41680 | D27: 3176514 | E27: =C27+D27 -> 3218194 | F27: 9322542.7 | G27: =F27-B27 -> -80078928 | H27: =IF(F27=0,0,E27/F27) -> 0.34520561 | I27: =IF(J27=0,0,E27/J27) -> 569.3903 | J27: 5652
B28: =SUM(B4:B27) -> 3.6204805e+09 | C28: =SUM(C4:C27) -> 1423467 | D28: =SUM(D4:D27) -> 96539053 | E28: =SUM(E4:E27) -> 97962520 | F28: =SUM(F4:F27) -> 3.494853e+08 | G28: =SUM(G4:G27) -> -3.2709952e+09 | H28: =SUM(H4:H27) -> 7.7432167 | I28: =SUM(I4:I27) -> 15238.744
A31: Cost Category | B31: Annual Value
A32: Procurement | B32: 8.247987e+10
A33: Freight | B33: 1423467
A34: Holding | B34: 96539053

Sheet Workforce & Ops
A1: WORKFORCE & OPERATIONS — DC EFFICIENCY & SAFETY METRICS
A3: Month | B3: Total Workforce | C3: Orders Processed | D3: Orders per Person per Day | E3: Avg Processing Time (hrs) | F3: Overtime Hours | G3: Absenteeism % | H3: Training Hours Completed | I3: Safety Incidents | J3: Equipment Downtime (hrs)
A4: Jan-2023 | B4: 50 | C4: 1845 | D4: 1.7 | E4: 1.6 | F4: 66 | G4: 5.3 | H4: 11 | I4: 1 | J4: 6.3
A5: Feb-2023 | B5: 50 | C5: 1087 | D5: 1 | E5: 2.2 | F5: 42 | G5: 5.7 | H5: 8 | I5: 3 | J5: 7.6
A6: Mar-2023 | B6: 50 | C6: 882 | D6: 0.8 | E6: 1.8 | F6: 82 | G6: 3.5 | H6: 12 | I6: 2 | J6: 2.6
A7: Apr-2023 | B7: 50 | C7: 2169 | D7: 2 | E7: 1.8 | F7: 66 | G7: 4.5 | H7: 18 | I7: 0 | J7: 1.3
A8: May-2023 | B8: 50 | C8: 2128 | D8: 1.9 | E8: 2 | F8: 110 | G8: 8.3 | H8: 12 | I8: 2 | J8: 5.1
A9: Jun-2023 | B9: 50 | C9: 1967 | D9: 1.8 | E9: 1.8 | F9: 103 | G9: 4.5 | H9: 6 | I9: 2 | J9: 3.6
A10: Jul-2023 | B10: 50 | C10: 1256 | D10: 1.1 | E10: 2.3 | F10: 65 | G10: 7.3 | H10: 15 | I10: 3 | J10: 6.5
A11: Aug-2023 | B11: 50 | C11: 2037 | D11: 1.9 | E11: 1.5 | F11: 37 | G11: 4.9 | H11: 11 | I11: 0 | J11: 4.6
A12: Sep-2023 | B12: 50 | C12: 1375 | D12: 1.2 | E12: 1.8 | F12: 43 | G12: 3 | H12: 7 | I12: 1 | J12: 3.9
A13: Oct-2023 | B13: 50 | C13: 1476 | D13: 1.3 | E13: 2.6 | F13: 81 | G13: 6.4 | H13: 19 | I13: 1 | J13: 5.1
A14: Nov-2023 | B14: 50 | C14: 2125 | D14: 1.9 | E14: 2.8 | F14: 22 | G14: 3.6 | H14: 8 | I14: 1 | J14: 1.9
A15: Dec-2023 | B15: 50 | C15: 1849 | D15: 1.7 | E15: 1.6 | F15: 93 | G15: 3 | H15: 9 | I15: 2 | J15: 7.5
... A27: Dec-2024 | B27: 50 | C27: 1220 | D27: 1.1 | E27: 2.5 | F27: 60 | G27: 4.7 | H27: 7 | I27: 1 | J27: 4
A30: TEAM PERFORMANCE BY SHIFT
A31: Shift | B31: Team Leader | C31: Team Size | D31: Avg Orders/Day | E31: Error Rate % | F31: OT % | G31: Performance Rating (1-5)
A32: Morning | B32: Rajesh Kumar | C32: 18 | D32: 342 | E32: 1.2 | F32: 8.5 | G32: 4
A33: Afternoon | B33: Priya Sharma | C33: 16 | D33: 298 | E33: 1.8 | F33: 12.3 | G33: 3
A34: Night | B34: Amit Patel | C34: 14 | D34: 256 | E34: 2.1 | F34: 15 | G34: 3
A35: Weekend | B35: Sunita Devi | C35: 10 | D35: 198 | E35: 0.9 | F35: 5.2 | G35: 5

Sheet What-If Simulator
A1: WHAT-IF SCENARIO SIMULATOR — DISTRIBUTION KPIS UNDER NEW ASSUMPTIONS
A3: INPUTS (Editable — Yellow Highlighted Cells)
A4: Desired OTD Target (%) | B4: 90
A5: Target Inventory Turnover | B5: 4.5
A6: Proposed Freight Cost Reduction (%) | B6: 10
A7: New Supplier Lead Time (days) | B7: 14
A8: Safety Stock Multiplier | B8: 1.5
A9: Workforce Target (orders/person/day) | B9: 20
A12: OUTPUTS (Auto-Calculated)
A13: Estimated Annual Freight Savings (₹) | B13: =SUM('Cost Analysis'!C4:C27)*B7/100 -> 199285.38
A14: New Stockout Rate (estimated) | B14: =COUNTIF('Raw Data'!U4:U323,"<"&'Raw Data'!W4:W323*(1+B9/10))/COUNTA('Raw Data'!U4:U323) -> 0.58934169
A15: New Inventory Holding Cost (₹) | B15: =SUM('Cost Analysis'!D4:D27)*(1+B9/10) -> 2.8961716e+08
A16: Estimated Service Level Improvement (%) | B16: =B4/100 - (1-AVERAGE('Logistics & Delivery'!F4:F8)) -> 0.11012047
A17: Projected Annual Cost Reduction (₹) | B17: =B13+B15 -> 2.8981644e+08
A18: Break-even Volume for new parameters | B18: =B17/'Cost Analysis'!B4 -> 1.1075466
A22: KPI | B22: Current | C22: Projected
A23: OTD % | B23: 82 | C23: 90
A24: Inventory Turnover | B24: 3.2 | C24: 4.5
A25: Freight Cost % | B25: 8.5 | C25: 7.2
A26: Stockout Rate | B26: 4.2 | C26: 3
A27: Lead Time | B27: 18 | C27: 14
A28: Productivity | B28: 16 | C28: 20
